Traceback (most recent call last):
  File "d:\programs\anaconda\envs\py35\lib\site-packages\jupyter_cache\executors\utils.py", line 56, in single_nb_execution
    record_timing=False,
  File "d:\programs\anaconda\envs\py35\lib\site-packages\nbclient\client.py", line 1082, in execute
    return NotebookClient(nb=nb, resources=resources, km=km, **kwargs).execute()
  File "d:\programs\anaconda\envs\py35\lib\site-packages\nbclient\util.py", line 74, in wrapped
    return just_run(coro(*args, **kwargs))
  File "d:\programs\anaconda\envs\py35\lib\site-packages\nbclient\util.py", line 53, in just_run
    return loop.run_until_complete(coro)
  File "d:\programs\anaconda\envs\py35\lib\asyncio\base_events.py", line 468, in run_until_complete
    return future.result()
  File "d:\programs\anaconda\envs\py35\lib\site-packages\nbclient\client.py", line 536, in async_execute
    cell, index, execution_count=self.code_cells_executed + 1
  File "d:\programs\anaconda\envs\py35\lib\site-packages\nbclient\client.py", line 827, in async_execute_cell
    self._check_raise_for_error(cell, exec_reply)
  File "d:\programs\anaconda\envs\py35\lib\site-packages\nbclient\client.py", line 735, in _check_raise_for_error
    raise CellExecutionError.from_cell_and_msg(cell, exec_reply['content'])
nbclient.exceptions.CellExecutionError: An error occurred while executing the following cell:
------------------
# –∏–º–ø–æ—Ä—Ç–∏—Ä—É–µ–º –±–∏–±–ª–∏–æ—Ç–µ–∫–∏ –¥–ª—è —Ä–∞–±–æ—Ç—ã —Å –¥–∞–Ω–Ω—ã–º–∏
import numpy as np # —ç—Ç–æ –±–∏–±–ª–∏–æ—Ç–µ–∫–∞ –¥–ª—è —Ä–∞–±–æ—Ç—ã —Å –º–∞—Å—Å–∏–≤–∞–º–∏ —á–∏—Å–µ–ª
import pandas as pd # —ç—Ç–æ –±–∏–±–ª–∏–æ—Ç–µ–∫–∞ –¥–ª—è —Ä–∞–±–æ—Ç—ã —Å –¥–∞—Ç–∞—Å–µ—Ç–∞–º–∏
import seaborn as sns # —ç—Ç–æ –±–∏–±–ª–∏–æ—Ç–µ–∫–∞ –¥–ª—è –≤–∏–∑—É–∞–ª–∏–∑–∞—Ü–∏–π

# —Å–ª–µ–¥—É—é—â–∞—è –º–∞–≥–∏—á–µ—Å–∫–∞—è –∫–æ–º–∞–Ω–¥–∞ –ø–æ–∑–≤–æ–ª—è–µ—Ç –æ—Ç–æ–±—Ä–∞–∂–∞—Ç—å –¥–∏–∞–≥—Ä–∞–º–º—ã –≤ —Ç–µ—Ç—Ä–∞–¥–∫–µ
%matplotlib inline
------------------

[1;31m---------------------------------------------------------------------------[0m
[1;31mImportError[0m                               Traceback (most recent call last)
[1;32mD:\Programs\Anaconda\envs\py_32bit\lib\site-packages\numpy\core\__init__.py[0m in [0;36m<module>[1;34m()[0m
[0;32m     15[0m [1;32mtry[0m[1;33m:[0m[1;33m[0m[0m
[1;32m---> 16[1;33m     [1;32mfrom[0m [1;33m.[0m [1;32mimport[0m [0mmultiarray[0m[1;33m[0m[0m
[0m[0;32m     17[0m [1;32mexcept[0m [0mImportError[0m [1;32mas[0m [0mexc[0m[1;33m:[0m[1;33m[0m[0m

[1;31mImportError[0m: cannot import name 'multiarray'

During handling of the above exception, another exception occurred:

[1;31mImportError[0m                               Traceback (most recent call last)
[1;32m<ipython-input-1-6f8f3d96664c>[0m in [0;36m<module>[1;34m()[0m
[0;32m      1[0m [1;31m# –∏–º–ø–æ—Ä—Ç–∏—Ä—É–µ–º –±–∏–±–ª–∏–æ—Ç–µ–∫–∏ –¥–ª—è —Ä–∞–±–æ—Ç—ã —Å –¥–∞–Ω–Ω—ã–º–∏[0m[1;33m[0m[1;33m[0m[0m
[1;32m----> 2[1;33m [1;32mimport[0m [0mnumpy[0m [1;32mas[0m [0mnp[0m [1;31m# —ç—Ç–æ –±–∏–±–ª–∏–æ—Ç–µ–∫–∞ –¥–ª—è —Ä–∞–±–æ—Ç—ã —Å –º–∞—Å—Å–∏–≤–∞–º–∏ —á–∏—Å–µ–ª[0m[1;33m[0m[0m
[0m[0;32m      3[0m [1;32mimport[0m [0mpandas[0m [1;32mas[0m [0mpd[0m [1;31m# —ç—Ç–æ –±–∏–±–ª–∏–æ—Ç–µ–∫–∞ –¥–ª—è —Ä–∞–±–æ—Ç—ã —Å –¥–∞—Ç–∞—Å–µ—Ç–∞–º–∏[0m[1;33m[0m[0m
[0;32m      4[0m [1;32mimport[0m [0mseaborn[0m [1;32mas[0m [0msns[0m [1;31m# —ç—Ç–æ –±–∏–±–ª–∏–æ—Ç–µ–∫–∞ –¥–ª—è –≤–∏–∑—É–∞–ª–∏–∑–∞—Ü–∏–π[0m[1;33m[0m[0m
[0;32m      5[0m [1;33m[0m[0m

[1;32mD:\Programs\Anaconda\envs\py_32bit\lib\site-packages\numpy\__init__.py[0m in [0;36m<module>[1;34m()[0m
[0;32m    140[0m         [1;32mreturn[0m [0mloader[0m[1;33m([0m[1;33m*[0m[0mpackages[0m[1;33m,[0m [1;33m**[0m[0moptions[0m[1;33m)[0m[1;33m[0m[0m
[0;32m    141[0m [1;33m[0m[0m
[1;32m--> 142[1;33m     [1;32mfrom[0m [1;33m.[0m [1;32mimport[0m [0madd_newdocs[0m[1;33m[0m[0m
[0m[0;32m    143[0m     __all__ = ['add_newdocs',
[0;32m    144[0m                [1;34m'ModuleDeprecationWarning'[0m[1;33m,[0m[1;33m[0m[0m

[1;32mD:\Programs\Anaconda\envs\py_32bit\lib\site-packages\numpy\add_newdocs.py[0m in [0;36m<module>[1;34m()[0m
[0;32m     11[0m [1;32mfrom[0m [0m__future__[0m [1;32mimport[0m [0mdivision[0m[1;33m,[0m [0mabsolute_import[0m[1;33m,[0m [0mprint_function[0m[1;33m[0m[0m
[0;32m     12[0m [1;33m[0m[0m
[1;32m---> 13[1;33m [1;32mfrom[0m [0mnumpy[0m[1;33m.[0m[0mlib[0m [1;32mimport[0m [0madd_newdoc[0m[1;33m[0m[0m
[0m[0;32m     14[0m [1;33m[0m[0m
[0;32m     15[0m [1;31m###############################################################################[0m[1;33m[0m[1;33m[0m[0m

[1;32mD:\Programs\Anaconda\envs\py_32bit\lib\site-packages\numpy\lib\__init__.py[0m in [0;36m<module>[1;34m()[0m
[0;32m      6[0m [1;32mfrom[0m [0mnumpy[0m[1;33m.[0m[0mversion[0m [1;32mimport[0m [0mversion[0m [1;32mas[0m [0m__version__[0m[1;33m[0m[0m
[0;32m      7[0m [1;33m[0m[0m
[1;32m----> 8[1;33m [1;32mfrom[0m [1;33m.[0m[0mtype_check[0m [1;32mimport[0m [1;33m*[0m[1;33m[0m[0m
[0m[0;32m      9[0m [1;32mfrom[0m [1;33m.[0m[0mindex_tricks[0m [1;32mimport[0m [1;33m*[0m[1;33m[0m[0m
[0;32m     10[0m [1;32mfrom[0m [1;33m.[0m[0mfunction_base[0m [1;32mimport[0m [1;33m*[0m[1;33m[0m[0m

[1;32mD:\Programs\Anaconda\envs\py_32bit\lib\site-packages\numpy\lib\type_check.py[0m in [0;36m<module>[1;34m()[0m
[0;32m      9[0m            'common_type']
[0;32m     10[0m [1;33m[0m[0m
[1;32m---> 11[1;33m [1;32mimport[0m [0mnumpy[0m[1;33m.[0m[0mcore[0m[1;33m.[0m[0mnumeric[0m [1;32mas[0m [0m_nx[0m[1;33m[0m[0m
[0m[0;32m     12[0m [1;32mfrom[0m [0mnumpy[0m[1;33m.[0m[0mcore[0m[1;33m.[0m[0mnumeric[0m [1;32mimport[0m [0masarray[0m[1;33m,[0m [0masanyarray[0m[1;33m,[0m [0marray[0m[1;33m,[0m [0misnan[0m[1;33m,[0m [0mzeros[0m[1;33m[0m[0m
[0;32m     13[0m [1;32mfrom[0m [1;33m.[0m[0mufunclike[0m [1;32mimport[0m [0misneginf[0m[1;33m,[0m [0misposinf[0m[1;33m[0m[0m

[1;32mD:\Programs\Anaconda\envs\py_32bit\lib\site-packages\numpy\core\__init__.py[0m in [0;36m<module>[1;34m()[0m
[0;32m     24[0m [0mOriginal[0m [0merror[0m [0mwas[0m[1;33m:[0m [1;33m%[0m[0ms[0m[1;33m[0m[0m
[0;32m     25[0m """ % (exc,)
[1;32m---> 26[1;33m     [1;32mraise[0m [0mImportError[0m[1;33m([0m[0mmsg[0m[1;33m)[0m[1;33m[0m[0m
[0m[0;32m     27[0m [1;32mfinally[0m[1;33m:[0m[1;33m[0m[0m
[0;32m     28[0m     [1;32mfor[0m [0menvkey[0m [1;32min[0m [0menv_added[0m[1;33m:[0m[1;33m[0m[0m

[1;31mImportError[0m: 
Importing the multiarray numpy extension module failed.  Most
likely you are trying to import a failed build of numpy.
If you're working with a numpy git repo, try `git clean -xdf` (removes all
files not under version control).  Otherwise reinstall numpy.

Original error was: cannot import name 'multiarray'

ImportError: 
Importing the multiarray numpy extension module failed.  Most
likely you are trying to import a failed build of numpy.
If you're working with a numpy git repo, try `git clean -xdf` (removes all
files not under version control).  Otherwise reinstall numpy.

Original error was: cannot import name 'multiarray'


