Traceback (most recent call last):
  File "d:\programs\anaconda\envs\py35\lib\site-packages\jupyter_cache\executors\utils.py", line 56, in single_nb_execution
    record_timing=False,
  File "d:\programs\anaconda\envs\py35\lib\site-packages\nbclient\client.py", line 1082, in execute
    return NotebookClient(nb=nb, resources=resources, km=km, **kwargs).execute()
  File "d:\programs\anaconda\envs\py35\lib\site-packages\nbclient\util.py", line 74, in wrapped
    return just_run(coro(*args, **kwargs))
  File "d:\programs\anaconda\envs\py35\lib\site-packages\nbclient\util.py", line 53, in just_run
    return loop.run_until_complete(coro)
  File "d:\programs\anaconda\envs\py35\lib\asyncio\base_events.py", line 468, in run_until_complete
    return future.result()
  File "d:\programs\anaconda\envs\py35\lib\site-packages\nbclient\client.py", line 536, in async_execute
    cell, index, execution_count=self.code_cells_executed + 1
  File "d:\programs\anaconda\envs\py35\lib\site-packages\nbclient\client.py", line 827, in async_execute_cell
    self._check_raise_for_error(cell, exec_reply)
  File "d:\programs\anaconda\envs\py35\lib\site-packages\nbclient\client.py", line 735, in _check_raise_for_error
    raise CellExecutionError.from_cell_and_msg(cell, exec_reply['content'])
nbclient.exceptions.CellExecutionError: An error occurred while executing the following cell:
------------------
ParameterFinder(initial=4.0).train(data[:, 0], data[:, 1], data[:, 2], epochs=10)
------------------

[1;31m---------------------------------------------------------------------------[0m
[1;31mTypeError[0m                                 Traceback (most recent call last)
[1;32m<ipython-input-9-8c249c01175b>[0m in [0;36m<module>[1;34m[0m
[1;32m----> 1[1;33m [0mParameterFinder[0m[1;33m([0m[0minitial[0m[1;33m=[0m[1;36m4.0[0m[1;33m)[0m[1;33m.[0m[0mtrain[0m[1;33m([0m[0mdata[0m[1;33m[[0m[1;33m:[0m[1;33m,[0m [1;36m0[0m[1;33m][0m[1;33m,[0m [0mdata[0m[1;33m[[0m[1;33m:[0m[1;33m,[0m [1;36m1[0m[1;33m][0m[1;33m,[0m [0mdata[0m[1;33m[[0m[1;33m:[0m[1;33m,[0m [1;36m2[0m[1;33m][0m[1;33m,[0m [0mepochs[0m[1;33m=[0m[1;36m10[0m[1;33m)[0m[1;33m[0m[0m
[0m
[1;32m<ipython-input-8-a2f74a94a1d9>[0m in [0;36m__init__[1;34m(self, initial)[0m
[0;32m      3[0m [1;32mclass[0m [0mParameterFinder[0m[1;33m:[0m[1;33m[0m[0m
[0;32m      4[0m     [1;32mdef[0m [0m__init__[0m[1;33m([0m[0mself[0m[1;33m,[0m [0minitial[0m[1;33m)[0m[1;33m:[0m[1;33m[0m[0m
[1;32m----> 5[1;33m         [0mself[0m[1;33m.[0m[0mk[0m [1;33m=[0m [0mtf[0m[1;33m.[0m[0mVariable[0m[1;33m([0m[0minitial[0m[1;33m,[0m [0mid[0m[1;33m=[0m[1;34m'unknown_k'[0m[1;33m)[0m[1;33m[0m[0m
[0m[0;32m      6[0m [1;33m[0m[0m
[0;32m      7[0m     [1;32mdef[0m [0mpredict[0m[1;33m([0m[0mself[0m[1;33m,[0m [0mX[0m[1;33m,[0m [0mY[0m[1;33m)[0m[1;33m:[0m[1;33m[0m[0m

[1;32mD:\Programs\Anaconda\envs\py35\lib\site-packages\tensorflow_core\python\ops\variables.py[0m in [0;36m__call__[1;34m(cls, *args, **kwargs)[0m
[0;32m    256[0m   [1;32mdef[0m [0m__call__[0m[1;33m([0m[0mcls[0m[1;33m,[0m [1;33m*[0m[0margs[0m[1;33m,[0m [1;33m**[0m[0mkwargs[0m[1;33m)[0m[1;33m:[0m[1;33m[0m[0m
[0;32m    257[0m     [1;32mif[0m [0mcls[0m [1;32mis[0m [0mVariableV1[0m[1;33m:[0m[1;33m[0m[0m
[1;32m--> 258[1;33m       [1;32mreturn[0m [0mcls[0m[1;33m.[0m[0m_variable_v1_call[0m[1;33m([0m[1;33m*[0m[0margs[0m[1;33m,[0m [1;33m**[0m[0mkwargs[0m[1;33m)[0m[1;33m[0m[0m
[0m[0;32m    259[0m     [1;32melif[0m [0mcls[0m [1;32mis[0m [0mVariable[0m[1;33m:[0m[1;33m[0m[0m
[0;32m    260[0m       [1;32mreturn[0m [0mcls[0m[1;33m.[0m[0m_variable_v2_call[0m[1;33m([0m[1;33m*[0m[0margs[0m[1;33m,[0m [1;33m**[0m[0mkwargs[0m[1;33m)[0m[1;33m[0m[0m

[1;31mTypeError[0m: _variable_v1_call() got an unexpected keyword argument 'id'
TypeError: _variable_v1_call() got an unexpected keyword argument 'id'

